🚀 开始处理模型: /data/nnotaa/align-anything/projects/Bio/outputs/Qwen2.5-7B-Instruct/slice_5380 (标签: local)
   - 清理后的模型名: _data_nnotaa_align-anything_projects_Bio_outputs_Qwen2.5-7B-Instruct_slice_5380
   - 创建输出目录: results/2025-10-22_17-10-06/_data_nnotaa_align-anything_projects_Bio_outputs_Qwen2.5-7B-Instruct_slice_5380
   - 正在运行 Animal toxin prediction 任务...
   - 正在运行 Animal toxin prediction 任务...
   - 正在运行 Animal toxin prediction 任务...
   - 正在运行 Animal toxin prediction 任务...
   - 正在运行 Animal toxin prediction 任务...
--- 开始执行推理任务 ---
  模型路径: /data/nnotaa/align-anything/projects/Bio/outputs/Qwen2.5-7B-Instruct/slice_5380
  模型标签: local
  输出目录: results/2025-10-22_17-10-06/_data_nnotaa_align-anything_projects_Bio_outputs_Qwen2.5-7B-Instruct_slice_5380/Animal
  温度: 0.0 0.7
  检测到 'local' 标签, 调用本地分布式推理脚本...
W1022 17:10:07.707000 89875 site-packages/torch/distributed/run.py:774] 
W1022 17:10:07.707000 89875 site-packages/torch/distributed/run.py:774] *****************************************
W1022 17:10:07.707000 89875 site-packages/torch/distributed/run.py:774] Setting OMP_NUM_THREADS environment variable for each process to be 1 in default, to avoid your system being overloaded, please further tune the variable for optimal performance in your application as needed. 
W1022 17:10:07.707000 89875 site-packages/torch/distributed/run.py:774] *****************************************
/data/nnotaa/miniconda3/envs/align-anything/bin/python3.11: can't open file '/data/nnotaa/align-anything/projects/Bio/benchmark/src/batch_inference_local.py': [Errno 2] No such file or directory
/data/nnotaa/miniconda3/envs/align-anything/bin/python3.11: can't open file '/data/nnotaa/align-anything/projects/Bio/benchmark/src/batch_inference_local.py': [Errno 2] No such file or directory
/data/nnotaa/miniconda3/envs/align-anything/bin/python3.11: can't open file '/data/nnotaa/align-anything/projects/Bio/benchmark/src/batch_inference_local.py': [Errno 2] No such file or directory
/data/nnotaa/miniconda3/envs/align-anything/bin/python3.11: can't open file '/data/nnotaa/align-anything/projects/Bio/benchmark/src/batch_inference_local.py': [Errno 2] No such file or directory
/data/nnotaa/miniconda3/envs/align-anything/bin/python3.11: can't open file '/data/nnotaa/align-anything/projects/Bio/benchmark/src/batch_inference_local.py': [Errno 2] No such file or directory
/data/nnotaa/miniconda3/envs/align-anything/bin/python3.11: can't open file '/data/nnotaa/align-anything/projects/Bio/benchmark/src/batch_inference_local.py': [Errno 2] No such file or directory
/data/nnotaa/miniconda3/envs/align-anything/bin/python3.11: can't open file '/data/nnotaa/align-anything/projects/Bio/benchmark/src/batch_inference_local.py': [Errno 2] No such file or directory
/data/nnotaa/miniconda3/envs/align-anything/bin/python3.11: can't open file '/data/nnotaa/align-anything/projects/Bio/benchmark/src/batch_inference_local.py': [Errno 2] No such file or directory
E1022 17:10:07.816000 89875 site-packages/torch/distributed/elastic/multiprocessing/api.py:874] failed (exitcode: 2) local_rank: 0 (pid: 89951) of binary: /data/nnotaa/miniconda3/envs/align-anything/bin/python3.11
Traceback (most recent call last):
  File "/data/nnotaa/miniconda3/envs/align-anything/bin/torchrun", line 7, in <module>
    sys.exit(main())
             ^^^^^^
  File "/data/nnotaa/miniconda3/envs/align-anything/lib/python3.11/site-packages/torch/distributed/elastic/multiprocessing/errors/__init__.py", line 357, in wrapper
    return f(*args, **kwargs)
           ^^^^^^^^^^^^^^^^^^
  File "/data/nnotaa/miniconda3/envs/align-anything/lib/python3.11/site-packages/torch/distributed/run.py", line 901, in main
    run(args)
  File "/data/nnotaa/miniconda3/envs/align-anything/lib/python3.11/site-packages/torch/distributed/run.py", line 892, in run
    elastic_launch(
  File "/data/nnotaa/miniconda3/envs/align-anything/lib/python3.11/site-packages/torch/distributed/launcher/api.py", line 143, in __call__
    return launch_agent(self._config, self._entrypoint, list(args))
           ^^^^^^^^^^^^^^^^^^^^^^^^^^^^^^^^^^^^^^^^^^^^^^^^^^^^^^^^
  File "/data/nnotaa/miniconda3/envs/align-anything/lib/python3.11/site-packages/torch/distributed/launcher/api.py", line 277, in launch_agent
    raise ChildFailedError(
torch.distributed.elastic.multiprocessing.errors.ChildFailedError: 
============================================================
src/batch_inference_local.py FAILED
------------------------------------------------------------
Failures:
[1]:
  time      : 2025-10-22_17:10:07
  host      : lyg0270
  rank      : 1 (local_rank: 1)
  exitcode  : 2 (pid: 89952)
  error_file: <N/A>
  traceback : To enable traceback see: https://pytorch.org/docs/stable/elastic/errors.html
[2]:
  time      : 2025-10-22_17:10:07
  host      : lyg0270
  rank      : 2 (local_rank: 2)
  exitcode  : 2 (pid: 89953)
  error_file: <N/A>
  traceback : To enable traceback see: https://pytorch.org/docs/stable/elastic/errors.html
[3]:
  time      : 2025-10-22_17:10:07
  host      : lyg0270
  rank      : 3 (local_rank: 3)
  exitcode  : 2 (pid: 89954)
  error_file: <N/A>
  traceback : To enable traceback see: https://pytorch.org/docs/stable/elastic/errors.html
[4]:
  time      : 2025-10-22_17:10:07
  host      : lyg0270
  rank      : 4 (local_rank: 4)
  exitcode  : 2 (pid: 89955)
  error_file: <N/A>
  traceback : To enable traceback see: https://pytorch.org/docs/stable/elastic/errors.html
[5]:
  time      : 2025-10-22_17:10:07
  host      : lyg0270
  rank      : 5 (local_rank: 5)
  exitcode  : 2 (pid: 89956)
  error_file: <N/A>
  traceback : To enable traceback see: https://pytorch.org/docs/stable/elastic/errors.html
[6]:
  time      : 2025-10-22_17:10:07
  host      : lyg0270
  rank      : 6 (local_rank: 6)
  exitcode  : 2 (pid: 89957)
  error_file: <N/A>
  traceback : To enable traceback see: https://pytorch.org/docs/stable/elastic/errors.html
[7]:
  time      : 2025-10-22_17:10:07
  host      : lyg0270
  rank      : 7 (local_rank: 7)
  exitcode  : 2 (pid: 89958)
  error_file: <N/A>
  traceback : To enable traceback see: https://pytorch.org/docs/stable/elastic/errors.html
------------------------------------------------------------
Root Cause (first observed failure):
[0]:
  time      : 2025-10-22_17:10:07
  host      : lyg0270
  rank      : 0 (local_rank: 0)
  exitcode  : 2 (pid: 89951)
  error_file: <N/A>
  traceback : To enable traceback see: https://pytorch.org/docs/stable/elastic/errors.html
============================================================
❌ [步骤 1/3] 推理步骤执行失败。请检查以上日志。
   - 正在运行 Bacteria exo prediction 任务...
   - 正在运行 Bacteria exo prediction 任务...
   - 正在运行 Bacteria exo prediction 任务...
   - 正在运行 Bacteria exo prediction 任务...
   - 正在运行 Bacteria exo prediction 任务...
--- 开始执行推理任务 ---
  模型路径: /data/nnotaa/align-anything/projects/Bio/outputs/Qwen2.5-7B-Instruct/slice_5380
  模型标签: local
  输出目录: results/2025-10-22_17-10-06/_data_nnotaa_align-anything_projects_Bio_outputs_Qwen2.5-7B-Instruct_slice_5380/Bacteria
  温度: 0.0 0.7
  检测到 'local' 标签, 调用本地分布式推理脚本...
W1022 17:10:09.218000 89961 site-packages/torch/distributed/run.py:774] 
W1022 17:10:09.218000 89961 site-packages/torch/distributed/run.py:774] *****************************************
W1022 17:10:09.218000 89961 site-packages/torch/distributed/run.py:774] Setting OMP_NUM_THREADS environment variable for each process to be 1 in default, to avoid your system being overloaded, please further tune the variable for optimal performance in your application as needed. 
W1022 17:10:09.218000 89961 site-packages/torch/distributed/run.py:774] *****************************************
/data/nnotaa/miniconda3/envs/align-anything/bin/python3.11: can't open file '/data/nnotaa/align-anything/projects/Bio/benchmark/src/batch_inference_local.py': [Errno 2] No such file or directory
/data/nnotaa/miniconda3/envs/align-anything/bin/python3.11: can't open file '/data/nnotaa/align-anything/projects/Bio/benchmark/src/batch_inference_local.py': [Errno 2] No such file or directory
/data/nnotaa/miniconda3/envs/align-anything/bin/python3.11: can't open file '/data/nnotaa/align-anything/projects/Bio/benchmark/src/batch_inference_local.py': [Errno 2] No such file or directory
/data/nnotaa/miniconda3/envs/align-anything/bin/python3.11: can't open file '/data/nnotaa/align-anything/projects/Bio/benchmark/src/batch_inference_local.py': [Errno 2] No such file or directory
/data/nnotaa/miniconda3/envs/align-anything/bin/python3.11: can't open file '/data/nnotaa/align-anything/projects/Bio/benchmark/src/batch_inference_local.py': [Errno 2] No such file or directory
/data/nnotaa/miniconda3/envs/align-anything/bin/python3.11: can't open file '/data/nnotaa/align-anything/projects/Bio/benchmark/src/batch_inference_local.py': [Errno 2] No such file or directory
/data/nnotaa/miniconda3/envs/align-anything/bin/python3.11: can't open file '/data/nnotaa/align-anything/projects/Bio/benchmark/src/batch_inference_local.py': [Errno 2] No such file or directory
/data/nnotaa/miniconda3/envs/align-anything/bin/python3.11: can't open file '/data/nnotaa/align-anything/projects/Bio/benchmark/src/batch_inference_local.py': [Errno 2] No such file or directory
E1022 17:10:09.328000 89961 site-packages/torch/distributed/elastic/multiprocessing/api.py:874] failed (exitcode: 2) local_rank: 0 (pid: 90034) of binary: /data/nnotaa/miniconda3/envs/align-anything/bin/python3.11
Traceback (most recent call last):
  File "/data/nnotaa/miniconda3/envs/align-anything/bin/torchrun", line 7, in <module>
    sys.exit(main())
             ^^^^^^
  File "/data/nnotaa/miniconda3/envs/align-anything/lib/python3.11/site-packages/torch/distributed/elastic/multiprocessing/errors/__init__.py", line 357, in wrapper
    return f(*args, **kwargs)
           ^^^^^^^^^^^^^^^^^^
  File "/data/nnotaa/miniconda3/envs/align-anything/lib/python3.11/site-packages/torch/distributed/run.py", line 901, in main
    run(args)
  File "/data/nnotaa/miniconda3/envs/align-anything/lib/python3.11/site-packages/torch/distributed/run.py", line 892, in run
    elastic_launch(
  File "/data/nnotaa/miniconda3/envs/align-anything/lib/python3.11/site-packages/torch/distributed/launcher/api.py", line 143, in __call__
    return launch_agent(self._config, self._entrypoint, list(args))
           ^^^^^^^^^^^^^^^^^^^^^^^^^^^^^^^^^^^^^^^^^^^^^^^^^^^^^^^^
  File "/data/nnotaa/miniconda3/envs/align-anything/lib/python3.11/site-packages/torch/distributed/launcher/api.py", line 277, in launch_agent
    raise ChildFailedError(
torch.distributed.elastic.multiprocessing.errors.ChildFailedError: 
============================================================
src/batch_inference_local.py FAILED
------------------------------------------------------------
Failures:
[1]:
  time      : 2025-10-22_17:10:09
  host      : lyg0270
  rank      : 1 (local_rank: 1)
  exitcode  : 2 (pid: 90035)
  error_file: <N/A>
  traceback : To enable traceback see: https://pytorch.org/docs/stable/elastic/errors.html
[2]:
  time      : 2025-10-22_17:10:09
  host      : lyg0270
  rank      : 2 (local_rank: 2)
  exitcode  : 2 (pid: 90036)
  error_file: <N/A>
  traceback : To enable traceback see: https://pytorch.org/docs/stable/elastic/errors.html
[3]:
  time      : 2025-10-22_17:10:09
  host      : lyg0270
  rank      : 3 (local_rank: 3)
  exitcode  : 2 (pid: 90037)
  error_file: <N/A>
  traceback : To enable traceback see: https://pytorch.org/docs/stable/elastic/errors.html
[4]:
  time      : 2025-10-22_17:10:09
  host      : lyg0270
  rank      : 4 (local_rank: 4)
  exitcode  : 2 (pid: 90038)
  error_file: <N/A>
  traceback : To enable traceback see: https://pytorch.org/docs/stable/elastic/errors.html
[5]:
  time      : 2025-10-22_17:10:09
  host      : lyg0270
  rank      : 5 (local_rank: 5)
  exitcode  : 2 (pid: 90039)
  error_file: <N/A>
  traceback : To enable traceback see: https://pytorch.org/docs/stable/elastic/errors.html
[6]:
  time      : 2025-10-22_17:10:09
  host      : lyg0270
  rank      : 6 (local_rank: 6)
  exitcode  : 2 (pid: 90040)
  error_file: <N/A>
  traceback : To enable traceback see: https://pytorch.org/docs/stable/elastic/errors.html
[7]:
  time      : 2025-10-22_17:10:09
  host      : lyg0270
  rank      : 7 (local_rank: 7)
  exitcode  : 2 (pid: 90041)
  error_file: <N/A>
  traceback : To enable traceback see: https://pytorch.org/docs/stable/elastic/errors.html
------------------------------------------------------------
Root Cause (first observed failure):
[0]:
  time      : 2025-10-22_17:10:09
  host      : lyg0270
  rank      : 0 (local_rank: 0)
  exitcode  : 2 (pid: 90034)
  error_file: <N/A>
  traceback : To enable traceback see: https://pytorch.org/docs/stable/elastic/errors.html
============================================================
❌ [步骤 1/3] 推理步骤执行失败。请检查以上日志。
✅ 模型 /data/nnotaa/align-anything/projects/Bio/outputs/Qwen2.5-7B-Instruct/slice_5380 处理完成。
-----------------------------------------
🚀 开始处理模型: Qwen/Qwen2.5-7B-Instruct (标签: local)
   - 清理后的模型名: Qwen_Qwen2.5-7B-Instruct
   - 创建输出目录: results/2025-10-22_17-10-06/Qwen_Qwen2.5-7B-Instruct
   - 正在运行 Animal toxin prediction 任务...
   - 正在运行 Animal toxin prediction 任务...
   - 正在运行 Animal toxin prediction 任务...
   - 正在运行 Animal toxin prediction 任务...
   - 正在运行 Animal toxin prediction 任务...
--- 开始执行推理任务 ---
  模型路径: Qwen/Qwen2.5-7B-Instruct
  模型标签: local
  输出目录: results/2025-10-22_17-10-06/Qwen_Qwen2.5-7B-Instruct/Animal
  温度: 0.0 0.7
  检测到 'local' 标签, 调用本地分布式推理脚本...
W1022 17:10:10.750000 90045 site-packages/torch/distributed/run.py:774] 
W1022 17:10:10.750000 90045 site-packages/torch/distributed/run.py:774] *****************************************
W1022 17:10:10.750000 90045 site-packages/torch/distributed/run.py:774] Setting OMP_NUM_THREADS environment variable for each process to be 1 in default, to avoid your system being overloaded, please further tune the variable for optimal performance in your application as needed. 
W1022 17:10:10.750000 90045 site-packages/torch/distributed/run.py:774] *****************************************
/data/nnotaa/miniconda3/envs/align-anything/bin/python3.11: can't open file '/data/nnotaa/align-anything/projects/Bio/benchmark/src/batch_inference_local.py': [Errno 2] No such file or directory
/data/nnotaa/miniconda3/envs/align-anything/bin/python3.11: can't open file '/data/nnotaa/align-anything/projects/Bio/benchmark/src/batch_inference_local.py': [Errno 2] No such file or directory
/data/nnotaa/miniconda3/envs/align-anything/bin/python3.11: can't open file '/data/nnotaa/align-anything/projects/Bio/benchmark/src/batch_inference_local.py': [Errno 2] No such file or directory
/data/nnotaa/miniconda3/envs/align-anything/bin/python3.11: can't open file '/data/nnotaa/align-anything/projects/Bio/benchmark/src/batch_inference_local.py': [Errno 2] No such file or directory
/data/nnotaa/miniconda3/envs/align-anything/bin/python3.11: can't open file '/data/nnotaa/align-anything/projects/Bio/benchmark/src/batch_inference_local.py': [Errno 2] No such file or directory
/data/nnotaa/miniconda3/envs/align-anything/bin/python3.11: can't open file '/data/nnotaa/align-anything/projects/Bio/benchmark/src/batch_inference_local.py': [Errno 2] No such file or directory
/data/nnotaa/miniconda3/envs/align-anything/bin/python3.11: can't open file '/data/nnotaa/align-anything/projects/Bio/benchmark/src/batch_inference_local.py': [Errno 2] No such file or directory
/data/nnotaa/miniconda3/envs/align-anything/bin/python3.11: can't open file '/data/nnotaa/align-anything/projects/Bio/benchmark/src/batch_inference_local.py': [Errno 2] No such file or directory
E1022 17:10:10.859000 90045 site-packages/torch/distributed/elastic/multiprocessing/api.py:874] failed (exitcode: 2) local_rank: 0 (pid: 90110) of binary: /data/nnotaa/miniconda3/envs/align-anything/bin/python3.11
Traceback (most recent call last):
  File "/data/nnotaa/miniconda3/envs/align-anything/bin/torchrun", line 7, in <module>
    sys.exit(main())
             ^^^^^^
  File "/data/nnotaa/miniconda3/envs/align-anything/lib/python3.11/site-packages/torch/distributed/elastic/multiprocessing/errors/__init__.py", line 357, in wrapper
    return f(*args, **kwargs)
           ^^^^^^^^^^^^^^^^^^
  File "/data/nnotaa/miniconda3/envs/align-anything/lib/python3.11/site-packages/torch/distributed/run.py", line 901, in main
    run(args)
  File "/data/nnotaa/miniconda3/envs/align-anything/lib/python3.11/site-packages/torch/distributed/run.py", line 892, in run
    elastic_launch(
  File "/data/nnotaa/miniconda3/envs/align-anything/lib/python3.11/site-packages/torch/distributed/launcher/api.py", line 143, in __call__
    return launch_agent(self._config, self._entrypoint, list(args))
           ^^^^^^^^^^^^^^^^^^^^^^^^^^^^^^^^^^^^^^^^^^^^^^^^^^^^^^^^
  File "/data/nnotaa/miniconda3/envs/align-anything/lib/python3.11/site-packages/torch/distributed/launcher/api.py", line 277, in launch_agent
    raise ChildFailedError(
torch.distributed.elastic.multiprocessing.errors.ChildFailedError: 
============================================================
src/batch_inference_local.py FAILED
------------------------------------------------------------
Failures:
[1]:
  time      : 2025-10-22_17:10:10
  host      : lyg0270
  rank      : 1 (local_rank: 1)
  exitcode  : 2 (pid: 90111)
  error_file: <N/A>
  traceback : To enable traceback see: https://pytorch.org/docs/stable/elastic/errors.html
[2]:
  time      : 2025-10-22_17:10:10
  host      : lyg0270
  rank      : 2 (local_rank: 2)
  exitcode  : 2 (pid: 90112)
  error_file: <N/A>
  traceback : To enable traceback see: https://pytorch.org/docs/stable/elastic/errors.html
[3]:
  time      : 2025-10-22_17:10:10
  host      : lyg0270
  rank      : 3 (local_rank: 3)
  exitcode  : 2 (pid: 90113)
  error_file: <N/A>
  traceback : To enable traceback see: https://pytorch.org/docs/stable/elastic/errors.html
[4]:
  time      : 2025-10-22_17:10:10
  host      : lyg0270
  rank      : 4 (local_rank: 4)
  exitcode  : 2 (pid: 90114)
  error_file: <N/A>
  traceback : To enable traceback see: https://pytorch.org/docs/stable/elastic/errors.html
[5]:
  time      : 2025-10-22_17:10:10
  host      : lyg0270
  rank      : 5 (local_rank: 5)
  exitcode  : 2 (pid: 90115)
  error_file: <N/A>
  traceback : To enable traceback see: https://pytorch.org/docs/stable/elastic/errors.html
[6]:
  time      : 2025-10-22_17:10:10
  host      : lyg0270
  rank      : 6 (local_rank: 6)
  exitcode  : 2 (pid: 90116)
  error_file: <N/A>
  traceback : To enable traceback see: https://pytorch.org/docs/stable/elastic/errors.html
[7]:
  time      : 2025-10-22_17:10:10
  host      : lyg0270
  rank      : 7 (local_rank: 7)
  exitcode  : 2 (pid: 90117)
  error_file: <N/A>
  traceback : To enable traceback see: https://pytorch.org/docs/stable/elastic/errors.html
------------------------------------------------------------
Root Cause (first observed failure):
[0]:
  time      : 2025-10-22_17:10:10
  host      : lyg0270
  rank      : 0 (local_rank: 0)
  exitcode  : 2 (pid: 90110)
  error_file: <N/A>
  traceback : To enable traceback see: https://pytorch.org/docs/stable/elastic/errors.html
============================================================
❌ [步骤 1/3] 推理步骤执行失败。请检查以上日志。
   - 正在运行 Bacteria exo prediction 任务...
   - 正在运行 Bacteria exo prediction 任务...
   - 正在运行 Bacteria exo prediction 任务...
   - 正在运行 Bacteria exo prediction 任务...
   - 正在运行 Bacteria exo prediction 任务...
--- 开始执行推理任务 ---
  模型路径: Qwen/Qwen2.5-7B-Instruct
  模型标签: local
  输出目录: results/2025-10-22_17-10-06/Qwen_Qwen2.5-7B-Instruct/Bacteria
  温度: 0.0 0.7
  检测到 'local' 标签, 调用本地分布式推理脚本...
W1022 17:10:12.267000 90120 site-packages/torch/distributed/run.py:774] 
W1022 17:10:12.267000 90120 site-packages/torch/distributed/run.py:774] *****************************************
W1022 17:10:12.267000 90120 site-packages/torch/distributed/run.py:774] Setting OMP_NUM_THREADS environment variable for each process to be 1 in default, to avoid your system being overloaded, please further tune the variable for optimal performance in your application as needed. 
W1022 17:10:12.267000 90120 site-packages/torch/distributed/run.py:774] *****************************************
/data/nnotaa/miniconda3/envs/align-anything/bin/python3.11: can't open file '/data/nnotaa/align-anything/projects/Bio/benchmark/src/batch_inference_local.py': [Errno 2] No such file or directory
/data/nnotaa/miniconda3/envs/align-anything/bin/python3.11: can't open file '/data/nnotaa/align-anything/projects/Bio/benchmark/src/batch_inference_local.py': [Errno 2] No such file or directory
/data/nnotaa/miniconda3/envs/align-anything/bin/python3.11: can't open file '/data/nnotaa/align-anything/projects/Bio/benchmark/src/batch_inference_local.py': [Errno 2] No such file or directory
/data/nnotaa/miniconda3/envs/align-anything/bin/python3.11: can't open file '/data/nnotaa/align-anything/projects/Bio/benchmark/src/batch_inference_local.py': [Errno 2] No such file or directory
/data/nnotaa/miniconda3/envs/align-anything/bin/python3.11: can't open file '/data/nnotaa/align-anything/projects/Bio/benchmark/src/batch_inference_local.py': [Errno 2] No such file or directory
/data/nnotaa/miniconda3/envs/align-anything/bin/python3.11: can't open file '/data/nnotaa/align-anything/projects/Bio/benchmark/src/batch_inference_local.py': [Errno 2] No such file or directory
/data/nnotaa/miniconda3/envs/align-anything/bin/python3.11: can't open file '/data/nnotaa/align-anything/projects/Bio/benchmark/src/batch_inference_local.py': [Errno 2] No such file or directory
/data/nnotaa/miniconda3/envs/align-anything/bin/python3.11: can't open file '/data/nnotaa/align-anything/projects/Bio/benchmark/src/batch_inference_local.py': [Errno 2] No such file or directory
E1022 17:10:12.376000 90120 site-packages/torch/distributed/elastic/multiprocessing/api.py:874] failed (exitcode: 2) local_rank: 0 (pid: 90186) of binary: /data/nnotaa/miniconda3/envs/align-anything/bin/python3.11
Traceback (most recent call last):
  File "/data/nnotaa/miniconda3/envs/align-anything/bin/torchrun", line 7, in <module>
    sys.exit(main())
             ^^^^^^
  File "/data/nnotaa/miniconda3/envs/align-anything/lib/python3.11/site-packages/torch/distributed/elastic/multiprocessing/errors/__init__.py", line 357, in wrapper
    return f(*args, **kwargs)
           ^^^^^^^^^^^^^^^^^^
  File "/data/nnotaa/miniconda3/envs/align-anything/lib/python3.11/site-packages/torch/distributed/run.py", line 901, in main
    run(args)
  File "/data/nnotaa/miniconda3/envs/align-anything/lib/python3.11/site-packages/torch/distributed/run.py", line 892, in run
    elastic_launch(
  File "/data/nnotaa/miniconda3/envs/align-anything/lib/python3.11/site-packages/torch/distributed/launcher/api.py", line 143, in __call__
    return launch_agent(self._config, self._entrypoint, list(args))
           ^^^^^^^^^^^^^^^^^^^^^^^^^^^^^^^^^^^^^^^^^^^^^^^^^^^^^^^^
  File "/data/nnotaa/miniconda3/envs/align-anything/lib/python3.11/site-packages/torch/distributed/launcher/api.py", line 277, in launch_agent
    raise ChildFailedError(
torch.distributed.elastic.multiprocessing.errors.ChildFailedError: 
============================================================
src/batch_inference_local.py FAILED
------------------------------------------------------------
Failures:
[1]:
  time      : 2025-10-22_17:10:12
  host      : lyg0270
  rank      : 1 (local_rank: 1)
  exitcode  : 2 (pid: 90187)
  error_file: <N/A>
  traceback : To enable traceback see: https://pytorch.org/docs/stable/elastic/errors.html
[2]:
  time      : 2025-10-22_17:10:12
  host      : lyg0270
  rank      : 2 (local_rank: 2)
  exitcode  : 2 (pid: 90188)
  error_file: <N/A>
  traceback : To enable traceback see: https://pytorch.org/docs/stable/elastic/errors.html
[3]:
  time      : 2025-10-22_17:10:12
  host      : lyg0270
  rank      : 3 (local_rank: 3)
  exitcode  : 2 (pid: 90189)
  error_file: <N/A>
  traceback : To enable traceback see: https://pytorch.org/docs/stable/elastic/errors.html
[4]:
  time      : 2025-10-22_17:10:12
  host      : lyg0270
  rank      : 4 (local_rank: 4)
  exitcode  : 2 (pid: 90190)
  error_file: <N/A>
  traceback : To enable traceback see: https://pytorch.org/docs/stable/elastic/errors.html
[5]:
  time      : 2025-10-22_17:10:12
  host      : lyg0270
  rank      : 5 (local_rank: 5)
  exitcode  : 2 (pid: 90191)
  error_file: <N/A>
  traceback : To enable traceback see: https://pytorch.org/docs/stable/elastic/errors.html
[6]:
  time      : 2025-10-22_17:10:12
  host      : lyg0270
  rank      : 6 (local_rank: 6)
  exitcode  : 2 (pid: 90192)
  error_file: <N/A>
  traceback : To enable traceback see: https://pytorch.org/docs/stable/elastic/errors.html
[7]:
  time      : 2025-10-22_17:10:12
  host      : lyg0270
  rank      : 7 (local_rank: 7)
  exitcode  : 2 (pid: 90193)
  error_file: <N/A>
  traceback : To enable traceback see: https://pytorch.org/docs/stable/elastic/errors.html
------------------------------------------------------------
Root Cause (first observed failure):
[0]:
  time      : 2025-10-22_17:10:12
  host      : lyg0270
  rank      : 0 (local_rank: 0)
  exitcode  : 2 (pid: 90186)
  error_file: <N/A>
  traceback : To enable traceback see: https://pytorch.org/docs/stable/elastic/errors.html
============================================================
❌ [步骤 1/3] 推理步骤执行失败。请检查以上日志。
✅ 模型 Qwen/Qwen2.5-7B-Instruct 处理完成。
-----------------------------------------
🎉 所有任务执行完毕！
